Workbook

Sheet DADOS
B1: STATEMENTS (mi) | D1: 2015 | E1: 2016 | F1: 2017 | G1: 2018 | H1: 2019 | I1: 2020 | J1: 2021 | K1: 2022 | L1: 2023 | M1: 2024
D2: 12/31/2015 | E2: 12/31/2016 | F2: 12/31/2017 | G2: 12/31/2018 | H2: 12/31/2019 | I2: 12/31/2020 | J2: 12/31/2021 | K2: 12/31/2022 | L2: 12/31/2023 | M2: 12/31/2024
B4: BALANÇO PATRIMONIAL
A6: (+) | B6: ACOp | D6: =SUM('Bal patrim - Padronizado'!C10,'Bal patrim - Padronizado'!C13,'Bal patrim - Padronizado'!C18,) -> 31.74 | E6: =SUM('Bal patrim - Padronizado'!D10,'Bal patrim - Padronizado'!D13,'Bal patrim - Padronizado'!D18,) -> 33.107 | F6: =SUM('Bal patrim - Padronizado'!E10,'Bal patrim - Padronizado'!E13,'Bal patrim - Padronizado'!E18,) -> 34.141 | G6: =SUM('Bal patrim - Padronizado'!F10,'Bal patrim - Padronizado'!F13,'Bal patrim - Padronizado'!F18,) -> 21.139 | H6: =SUM('Bal patrim - Padronizado'!G10,'Bal patrim - Padronizado'!G13,'Bal patrim - Padronizado'!G18,) -> 23.61 | I6: =SUM('Bal patrim - Padronizado'!H10,'Bal patrim - Padronizado'!H13,'Bal patrim - Padronizado'!H18,) -> 23.888 | J6: =SUM('Bal patrim - Padronizado'!I10,'Bal patrim - Padronizado'!I13,'Bal patrim - Padronizado'!I18,) -> 43.215 | K6: =SUM('Bal patrim - Padronizado'!J10,'Bal patrim - Padronizado'!J13,'Bal patrim - Padronizado'!J18,) -> 47.297 | ... M6: =SUM('Bal patrim - Padronizado'!L10,'Bal patrim - Padronizado'!L13,'Bal patrim - Padronizado'!L18,) -> 63.12
A7: (-) | B7: PCOp | D7: =-SUM('Bal patrim - Padronizado'!C38,'Bal patrim - Padronizado'!C47,) -> -6.455 | E7: =-SUM('Bal patrim - Padronizado'!D38,'Bal patrim - Padronizado'!D47,) -> -3.225 | F7: =-SUM('Bal patrim - Padronizado'!E38,'Bal patrim - Padronizado'!E47,) -> -1.726 | G7: =-SUM('Bal patrim - Padronizado'!F38,'Bal patrim - Padronizado'!F47,) -> -1.925 | H7: =-SUM('Bal patrim - Padronizado'!G38,'Bal patrim - Padronizado'!G47,) -> -3.655 | I7: =-SUM('Bal patrim - Padronizado'!H38,'Bal patrim - Padronizado'!H47,) -> -6.761 | J7: =-SUM('Bal patrim - Padronizado'!I38,'Bal patrim - Padronizado'!I47,) -> -10.185 | K7: =-SUM('Bal patrim - Padronizado'!J38,'Bal patrim - Padronizado'!J47,) -> -20.362 | ... M7: =-SUM('Bal patrim - Padronizado'!L38,'Bal patrim - Padronizado'!L47,) -> -17.905
A8: (=) | B8: IOG | D8: =SUM(D6:D7) -> 25.285 | E8: =SUM(E6:E7) -> 29.882 | F8: =SUM(F6:F7) -> 32.415 | G8: =SUM(G6:G7) -> 19.214 | H8: =SUM(H6:H7) -> 19.955 | I8: =SUM(I6:I7) -> 17.127 | J8: =SUM(J6:J7) -> 33.03 | K8: =SUM(K6:K7) -> 26.935 | ... M8: =SUM(M6:M7) -> 45.215
A9: (+) | B9: AñC | D9: ='Bal patrim - Padronizado'!C34 -> 15.37 | E9: ='Bal patrim - Padronizado'!D34 -> 18.735 | F9: ='Bal patrim - Padronizado'!E34 -> 1.705 | G9: ='Bal patrim - Padronizado'!F34 -> 153.849 | H9: ='Bal patrim - Padronizado'!G34 -> 150.299 | I9: ='Bal patrim - Padronizado'!H34 -> 152.686 | J9: ='Bal patrim - Padronizado'!I34 -> 215.111 | K9: ='Bal patrim - Padronizado'!J34 -> 232.091 | ... M9: ='Bal patrim - Padronizado'!L34 -> 272.316
B10: Capital Investido | D10: =SUM(D8:D9) -> 40.655 | E10: =SUM(E8:E9) -> 48.617 | F10: =SUM(F8:F9) -> 34.12 | G10: =SUM(G8:G9) -> 173.063 | H10: =SUM(H8:H9) -> 170.254 | I10: =SUM(I8:I9) -> 169.813 | J10: =SUM(J8:J9) -> 248.141 | K10: =SUM(K8:K9) -> 259.026 | ... M10: =SUM(M8:M9) -> 317.531
B12: Variação dos dois métodos | D12: =D10-D19 -> 0 | E12: =E10-E19 -> 0 | F12: =F10-F19 -> 0 | G12: =G10-G19 -> 0 | H12: =H10-H19 -> 0 | I12: =I10-I19 -> 0 | J12: =J10-J19 -> 0 | K12: =K10-K19 -> 0 | ... M12: =M10-M19 -> 0
A14: (+) | B14: PCFin | D14: ='Bal patrim - Padronizado'!C43 -> 0.61 | E14: ='Bal patrim - Padronizado'!D43 -> 0.735 | F14: ='Bal patrim - Padronizado'!E43 -> 0.733 | G14: ='Bal patrim - Padronizado'!F43 -> 0.731 | H14: ='Bal patrim - Padronizado'!G43 -> 0.511 | I14: ='Bal patrim - Padronizado'!H43 -> 0.203 | J14: ='Bal patrim - Padronizado'!I43 -> 0.202 | K14: ='Bal patrim - Padronizado'!J43 -> 0.202 | ... M14: ='Bal patrim - Padronizado'!L43 -> 0.088
A15: (-) | B15: ACFin | D15: =-'Bal patrim - Padronizado'!C7 -> -42.264 | E15: =-'Bal patrim - Padronizado'!D7 -> -35.774 | F15: =-'Bal patrim - Padronizado'!E7 -> -18.945 | G15: =-'Bal patrim - Padronizado'!F7 -> -31.212 | H15: =-'Bal patrim - Padronizado'!G7 -> -51.746 | I15: =-'Bal patrim - Padronizado'!H7 -> -31.209 | J15: =-'Bal patrim - Padronizado'!I7 -> -17.619 | K15: =-'Bal patrim - Padronizado'!J7 -> -21.331 | ... M15: =-'Bal patrim - Padronizado'!L7 -> -7.321
A16: (=) | B16: Tesouraria | D16: =SUM(D14:D15) -> -41.654 | E16: =SUM(E14:E15) -> -35.039 | F16: =SUM(F14:F15) -> -18.212 | G16: =SUM(G14:G15) -> -30.481 | H16: =SUM(H14:H15) -> -51.235 | I16: =SUM(I14:I15) -> -31.006 | J16: =SUM(J14:J15) -> -17.417 | K16: =SUM(K14:K15) -> -21.129 | ... M16: =SUM(M14:M15) -> -7.233
A17: (+) | B17: PñC | D17: ='Bal patrim - Padronizado'!C62 -> 3.891 | E17: ='Bal patrim - Padronizado'!D62 -> 7.45 | F17: ='Bal patrim - Padronizado'!E62 -> 7.397 | G17: ='Bal patrim - Padronizado'!F62 -> 7.79 | H17: ='Bal patrim - Padronizado'!G62 -> 7.143 | I17: ='Bal patrim - Padronizado'!H62 -> 13.36 | J17: ='Bal patrim - Padronizado'!I62 -> 18.04 | K17: ='Bal patrim - Padronizado'!J62 -> 19.423 | ... M17: ='Bal patrim - Padronizado'!L62 -> 71.852
A18: (+) | B18: PL | D18: ='Bal patrim - Padronizado'!C72 -> 78.418 | E18: ='Bal patrim - Padronizado'!D72 -> 76.206 | F18: ='Bal patrim - Padronizado'!E72 -> 44.935 | G18: ='Bal patrim - Padronizado'!F72 -> 195.754 | H18: ='Bal patrim - Padronizado'!G72 -> 214.346 | I18: ='Bal patrim - Padronizado'!H72 -> 187.459 | J18: ='Bal patrim - Padronizado'!I72 -> 247.518 | K18: ='Bal patrim - Padronizado'!J72 -> 260.732 | ... M18: ='Bal patrim - Padronizado'!L72 -> 252.912
B19: Capital Investido | D19: =SUM(D16:D18) -> 40.655 | E19: =SUM(E16:E18) -> 48.617 | F19: =SUM(F16:F18) -> 34.12 | G19: =SUM(G16:G18) -> 173.063 | H19: =SUM(H16:H18) -> 170.254 | I19: =SUM(I16:I18) -> 169.813 | J19: =SUM(J16:J18) -> 248.141 | K19: =SUM(K16:K18) -> 259.026 | ... M19: =SUM(M16:M18) -> 317.531
A21: (=) | B21: Investimento Líquido | D21: 0 | E21: =-(E19-D19) -> -7.962 | F21: =-(F19-E19) -> 14.497 | G21: =-(G19-F19) -> -138.943 | H21: =-(H19-G19) -> 2.809 | I21: =-(I19-H19) -> 0.441 | J21: =-(J19-I19) -> -78.328 | K21: =-(K19-J19) -> -10.885 | L21: =-(L19-K19) -> -11.238 | M21: =-(M19-L19) -> -47.267
B24: D.R.E
A26: (+) | B26: Lucro Operacional (LAJIR) | E26: ='DRE - Ajustado 3º TRI 2025'!C20 -> 16.399 | F26: ='DRE - Ajustado 3º TRI 2025'!D20 -> 12.666 | G26: ='DRE - Ajustado 3º TRI 2025'!E20 -> 22.903 | H26: ='DRE - Ajustado 3º TRI 2025'!F20 -> 24.961 | I26: ='DRE - Ajustado 3º TRI 2025'!G20 -> 19.171 | J26: ='DRE - Ajustado 3º TRI 2025'!H20 -> 103.23 | K26: ='DRE - Ajustado 3º TRI 2025'!I20 -> 38.323 | L26: ='DRE - Ajustado 3º TRI 2025'!J20 -> 30.123 | M26: ='DRE - Ajustado 3º TRI 2025'!K20 -> 43.628
A27: (-) | B27: Alíquota IR (do LAIR) | E27: ='DRE - Ajustado 3º TRI 2025'!C31/'DRE - Ajustado 3º TRI 2025'!C30 -> 0.32721194 | F27: ='DRE - Ajustado 3º TRI 2025'!D31/'DRE - Ajustado 3º TRI 2025'!D30 -> 0.16240632 | G27: ='DRE - Ajustado 3º TRI 2025'!E31/'DRE - Ajustado 3º TRI 2025'!E30 -> 0.069491874 | H27: ='DRE - Ajustado 3º TRI 2025'!F31/'DRE - Ajustado 3º TRI 2025'!F30 -> 0.076661549 | I27: ='DRE - Ajustado 3º TRI 2025'!G31/'DRE - Ajustado 3º TRI 2025'!G30 -> 0.084462931 | J27: ='DRE - Ajustado 3º TRI 2025'!H31/'DRE - Ajustado 3º TRI 2025'!H30 -> 0.041818671 | K27: ='DRE - Ajustado 3º TRI 2025'!I31/'DRE - Ajustado 3º TRI 2025'!I30 -> 0.088876467 | L27: ='DRE - Ajustado 3º TRI 2025'!J31/'DRE - Ajustado 3º TRI 2025'!J30 -> 0.098042911 | M27: ='DRE - Ajustado 3º TRI 2025'!K31/'DRE - Ajustado 3º TRI 2025'!K30 -> 0.23857152
A28: (=) | B28: NOPAT | D28: =D26*(1-D27) -> 0 | E28: =E26*(1-E27) -> 11.033051 | F28: =F26*(1-F27) -> 10.608962 | G28: =G26*(1-G27) -> 21.311428 | H28: =H26*(1-H27) -> 23.047451 | I28: =I26*(1-I27) -> 17.551761 | J28: =J26*(1-J27) -> 98.913059 | K28: =K26*(1-K27) -> 34.916987 | ... M28: =M26*(1-M27) -> 33.219602
A30: (=) | B30: FLUXO DE CAIXA LIVRE (FCLE) | D30: =SUM(D28,D21) -> 0 | E30: =SUM(E28,E21) -> 3.0710514 | F30: =SUM(F28,F21) -> 25.105962 | G30: =SUM(G28,G21) -> -117.63157 | H30: =SUM(H28,H21) -> 25.856451 | I30: =SUM(I28,I21) -> 17.992761 | J30: =SUM(J28,J21) -> 20.585059 | K30: =SUM(K28,K21) -> 24.031987 | ... M30: =SUM(M28,M21) -> -14.047398
B34: ROIC | C34: =EXP(C35)-1 -> 0.24223623 | E34: =E28/D19 -> 0.2713824 | F34: =F28/E19 -> 0.21821506 | G34: =G28/F19 -> 0.62460222 | H34: =H28/G19 -> 0.13317376 | I34: =I28/H19 -> 0.10309162 | J34: =J28/I19 -> 0.58248225 | K34: =K28/J19 -> 0.1407143 | L34: =L28/K19 -> 0.10489161 | M34: =M28/L19 -> 0.12291538
B35: ln(1+ROIC) | C35: =AVERAGE(E35:M35) -> 0.21691317 | E35: =LN(1+E34) -> 0.24010481 | F35: =LN(1+F34) -> 0.19738672 | G35: =LN(1+G34) -> 0.485263 | H35: =LN(1+H34) -> 0.12502234 | I35: =LN(1+I34) -> 0.098116804 | J35: =LN(1+J34) -> 0.45899466 | K35: =LN(1+K34) -> 0.13165465 | L35: =LN(1+L34) -> 0.099747237 | M35: =LN(1+M34) -> 0.11592832
B36: b (taxa de retenção) | C36: =C38/C34 -> 1.059162 | E36: =E38/E34 -> 0.72164986 | F36: =F38/F34 -> -1.3664862 | G36: =G38/G34 -> 6.5196477 | H36: =H38/H34 -> -0.12187899 | I36: =I38/I34 -> -0.025125684 | J36: =J38/J34 -> 0.79188735 | K36: =K38/K34 -> 0.31173938 | L36: =L38/L34 -> 0.41362324 | M36: =M38/M34 -> 1.4228647
B37: g (=ROIC * b) | C37: =C34*C36 -> 0.25656742 | E37: =E34*E36 -> 0.19584307 | F37: =F34*F36 -> -0.29818788 | G37: =G34*G36 -> 4.0721864 | H37: =H34*H36 -> -0.016231083 | I37: =I34*I36 -> -0.0025902475 | J37: =J34*J36 -> 0.46126033 | K37: =K34*K36 -> 0.043866189 | L37: =L34*L36 -> 0.043385606 | M37: =M34*M36 -> 0.17489196
B38: g (CapInvest) | C38: =EXP(C39)-1 -> 0.25656742 | E38: =E19/D19-1 -> 0.19584307 | F38: =F19/E19-1 -> -0.29818788 | G38: =G19/F19-1 -> 4.0721864 | H38: =H19/G19-1 -> -0.016231083 | I38: =I19/H19-1 -> -0.0025902475 | J38: =J19/I19-1 -> 0.46126033 | K38: =K19/J19-1 -> 0.043866189 | L38: =L19/K19-1 -> 0.043385606 | M38: =M19/L19-1 -> 0.17489196
B39: ln[1+g(CapInvest)] | C39: =AVERAGE(E39:M39) -> 0.22838374 | E39: =LN(1+E38) -> 0.17885143 | F39: =LN(1+F38) -> -0.35408954 | G39: =LN(1+G38) -> 1.623772 | H39: =LN(1+H38) -> -0.01636425 | I39: =LN(1+I38) -> -0.002593608 | J39: =LN(1+J38) -> 0.3792993 | K39: =LN(1+K38) -> 0.04293131 | L39: =LN(1+L38) -> 0.042470816 | M39: =LN(1+M38) -> 0.16117619
B41: Receita | E41: ='DRE - Ajustado 3º TRI 2025'!C6 -> 31.353 | F41: ='DRE - Ajustado 3º TRI 2025'!D6 -> 23.646 | G41: ='DRE - Ajustado 3º TRI 2025'!E6 -> 33.684 | H41: ='DRE - Ajustado 3º TRI 2025'!F6 -> 38.621 | I41: ='DRE - Ajustado 3º TRI 2025'!G6 -> 35.93 | J41: ='DRE - Ajustado 3º TRI 2025'!H6 -> 120.319 | K41: ='DRE - Ajustado 3º TRI 2025'!I6 -> 72.058 | L41: ='DRE - Ajustado 3º TRI 2025'!J6 -> 67.307 | M41: ='DRE - Ajustado 3º TRI 2025'!K6 -> 85.999
B42: g(Receita) | C42: =EXP(C43)-1 -> 0.13442761 | D42: n/a | E42: n/a | F42: =F41/E41-1 -> -0.2458138 | G42: =G41/F41-1 -> 0.42451155 | H42: =H41/G41-1 -> 0.1465681 | I42: =I41/H41-1 -> -0.069677119 | J42: =J41/I41-1 -> 2.3487058 | K42: =K41/J41-1 -> -0.40110872 | L42: =L41/K41-1 -> -0.065932998 | M42: =M41/L41-1 -> 0.27771257
B43: ln[1+g(Rec)] | C43: =AVERAGE(F43:M43) -> 0.12612821 | D43: n/a | E43: n/a | F43: =LN(1+F42) -> -0.28211599 | G43: =LN(1+G42) -> 0.35382898 | H43: =LN(1+H42) -> 0.13677322 | I43: =LN(1+I42) -> -0.072223569 | J43: =LN(1+J42) -> 1.2085739 | K43: =LN(1+K42) -> -0.5126752 | L43: =LN(1+L42) -> -0.068207107 | M43: =LN(1+M42) -> 0.24507143
B45: WACC 2024 | C45: 0.151
B47: n/a -> não aplicável

Sheet ESTRUTURA DE CAPITAL
B1: STATEMENTS (mi) | D1: 2017 | E1: 2018 | F1: 2019 | G1: 2020 | H1: 2021 | I1: 2022 | J1: 2023 | K1: 2024 | L1: 3º tri. 2025 (mi.) | O1: 3º tri. (Milhares) | P1: 3º tri.
D2: 12/31/2017 | E2: 12/31/2018 | F2: 12/31/2019 | G2: 12/31/2020 | H2: 12/31/2021 | I2: 12/31/2022 | J2: 12/31/2023 | K2: 12/31/2024 | L2: 09/30/2025 | O2: 09/30/2025 | P2: 09/30/2025
B4: BALANÇO PATRIMONIAL
B6: Dívida Financeira CP | D6: ='Bal patrim - Padronizado'!E43 -> 0.733 | E6: ='Bal patrim - Padronizado'!F43 -> 0.731 | F6: ='Bal patrim - Padronizado'!G43 -> 0.511 | G6: ='Bal patrim - Padronizado'!H43 -> 0.203 | H6: ='Bal patrim - Padronizado'!I43 -> 0.202 | I6: ='Bal patrim - Padronizado'!J43 -> 0.202 | J6: ='Bal patrim - Padronizado'!K43 -> 0.134 | K6: ='Bal patrim - Padronizado'!L43 -> 0.088 | L6: =O6/1000 -> 1.049 | O6: 1049 | P6: =TRIM('Bal patrim B3 - 3º TRI 2025'!C24) -> 1.049
B7: Dívida Financeira LP | D7: ='Bal patrim - Padronizado'!E52 -> 1.972 | E7: ='Bal patrim - Padronizado'!F52 -> 1.245 | F7: ='Bal patrim - Padronizado'!G52 -> 0.737 | G7: ='Bal patrim - Padronizado'!H52 -> 0.536 | H7: ='Bal patrim - Padronizado'!I52 -> 0.335 | I7: ='Bal patrim - Padronizado'!J52 -> 0.134 | J7: ='Bal patrim - Padronizado'!K52 -> 0 | K7: ='Bal patrim - Padronizado'!L52 -> 30.706 | L7: =O7/1000 -> 26.373 | O7: 26373 | P7: =TRIM('Bal patrim B3 - 3º TRI 2025'!C58) -> 26.373
A8: (=) | B8: Dívida Bruta Total | D8: =SUM(D6:D7) -> 2.705 | E8: =SUM(E6:E7) -> 1.976 | F8: =SUM(F6:F7) -> 1.248 | G8: =SUM(G6:G7) -> 0.739 | H8: =SUM(H6:H7) -> 0.537 | I8: =SUM(I6:I7) -> 0.336 | J8: =SUM(J6:J7) -> 0.134 | K8: =SUM(K6:K7) -> 30.794 | L8: =SUM(L6:L7) -> 27.422 | O8: =SUM(O6:O7) -> 27422 | P8: =SUM(P6:P7) -> 0
B9: Capitalização de mercado | D9: 313.5325 | E9: 350.1218 | F9: 698.9818 | G9: 622.0181 | H9: 559.564 | I9: 584.798 | J9: 541.9002 | K9: 451.0578 | L9: 455.47153
B10: Peso da Dívida (Wd) | D10: =D8/(D8+D9) -> 0.0085536978 | E10: =E8/(E8+E9) -> 0.0056120771 | F10: =F8/(F8+F9) -> 0.001782272 | G10: =G8/(G8+G9) -> 0.0011866585 | H10: =H8/(H8+H9) -> 0.00095875565 | I10: =I8/(I8+I9) -> 0.00057422744 | J10: =J8/(J8+J9) -> 0.00024721687 | K10: =K8/(K8+K9) -> 0.063907616 | L10: =L8/(L8+L9) -> 0.056786844
B11: Peso do Capital Próprio (Wpl) | D11: =D9/(D8+D9) -> 0.9914463 | E11: =E9/(E8+E9) -> 0.99438792 | F11: =F9/(F8+F9) -> 0.99821773 | G11: =G9/(G8+G9) -> 0.99881334 | H11: =H9/(H8+H9) -> 0.99904124 | I11: =I9/(I8+I9) -> 0.99942577 | J11: =J9/(J8+J9) -> 0.99975278 | K11: =K9/(K8+K9) -> 0.93609238 | L11: =L9/(L8+L9) -> 0.94321316
B13: DRE
B15: "Despesa com juros" | D15: =('DRE - Ajustado 3º TRI 2025'!D23) -> 0.157 | E15: =('DRE - Ajustado 3º TRI 2025'!E23) -> 0.121 | F15: =('DRE - Ajustado 3º TRI 2025'!F23) -> 0.086 | G15: =('DRE - Ajustado 3º TRI 2025'!G23) -> 0.053 | H15: =('DRE - Ajustado 3º TRI 2025'!H23) -> 0.037 | I15: =('DRE - Ajustado 3º TRI 2025'!I23) -> 0.025 | J15: =('DRE - Ajustado 3º TRI 2025'!J23) -> 0.014 | K15: =('DRE - Ajustado 3º TRI 2025'!K23) -> 0.105 | L15: =('DRE - Ajustado 3º TRI 2025'!L23) -> 1.313
B16: Despesa de Juros acumulada | D16: =D15 -> 0.157 | E16: =E15 -> 0.121 | F16: =F15 -> 0.086 | G16: =G15 -> 0.053 | H16: =H15 -> 0.037 | I16: =I15 -> 0.025 | J16: =J15 -> 0.014 | K16: =K15 -> 0.105 | L16: =L15 -> 1.313
B17: Despesa de Juros da dívida | D17: =D16/D8 -> 0.058040665 | E17: =E16/E8 -> 0.061234818 | F17: =F16/F8 -> 0.068910256 | G17: =G16/G8 -> 0.071718539 | H17: =H16/H8 -> 0.068901304 | I17: =I16/I8 -> 0.074404762 | J17: =J16/J8 -> 0.10447761 | K17: =K16/K8 -> 0.0034097551 | L17: =L16/L8 -> 0.047881263
B20: Custo de Cap. Próprio (Kpl) Brasil | C20: =C26+(C27*(C28-C26)) -> 0.15149278
B21: Modelo CAPM
B23: 𝐾𝑒 = 𝑅𝑓 + β ∗ (𝑅𝑚 − 𝑅𝑓)
B25: Dados do dia 30/10/2025
B26: RF -> Taxa livre de risco - SELIC | C26: 0.151633
B27: β -> Beta ajustado da AFLT3 | C27: 0.077
B28: RM -> Retorno esperado do merc. | C28: 0.149812
B30: Alíquota IR (sob o LAIR) | D30: =DADOS!F27 -> 0.16240632 | E30: =DADOS!G27 -> 0.069491874 | F30: =DADOS!H27 -> 0.076661549 | G30: =DADOS!I27 -> 0.084462931 | H30: =DADOS!J27 -> 0.041818671 | I30: =DADOS!K27 -> 0.088876467 | J30: =DADOS!L27 -> 0.098042911 | K30: =DADOS!M27 -> 0.23857152 | L30: ='DRE - Ajustado 3º TRI 2025'!L31/'DRE - Ajustado 3º TRI 2025'!L30 -> 0.29344521
B31: WACC | K31: 0.151 | L31: =(L11*C20)+(L10*(L17*(1-L30))) -> 0.14481113
B32: 𝑊𝐴𝐶𝐶=𝑤_𝑃𝐿 (𝑘_𝑃𝐿 )+𝑤_𝐷 [𝑘_𝐷 (1−𝑖𝑟)]

Sheet Aval. Fluxo de Caixa Descontado
A1: VALORES EM MILHÕES (mi.) | C1: 2019 | D1: 2020 | E1: 2021 | F1: 2022 | G1: 2023 | H1: 2024 | I1: 2025 | J1: =I1+1 -> 2026 | K1: =J1+1 -> 2027 | L1: =K1+1 -> 2028 | M1: =L1+1 -> 2029 | N1: =M1+1 -> 2030 | O1: =N1+1 -> 2031 | P1: =O1+1 -> 2032 | Q1: =P1+1 -> 2033 | R1: =Q1+1 -> 2034
B3: RECEITA | C3: ='DRE - Ajustado 3º TRI 2025'!F6 -> 38.621 | D3: ='DRE - Ajustado 3º TRI 2025'!G6 -> 35.93 | E3: ='DRE - Ajustado 3º TRI 2025'!H6 -> 120.319 | F3: ='DRE - Ajustado 3º TRI 2025'!I6 -> 72.058 | G3: ='DRE - Ajustado 3º TRI 2025'!J6 -> 67.307 | H3: ='DRE - Ajustado 3º TRI 2025'!K6 -> 85.999 | I3: ='Projeção DRE'!K3 -> 81.447 | J3: ='Projeção DRE'!L3 -> 86.813486 | K3: ='Projeção DRE'!M3 -> 92.03559 | L3: ='Projeção DRE'!N3 -> 97.043889 | M3: ='Projeção DRE'!O3 -> 101.76806 | N3: ='Projeção DRE'!P3 -> 106.13846 | O3: ='Projeção DRE'!Q3 -> 110.08771 | P3: ='Projeção DRE'!R3 -> 113.55243 | ... R3: ='Projeção DRE'!T3 -> 118.80433
B4: EBIT(LAJIR) | C4: ='Projeção DRE'!E13 -> 24.961 | D4: ='Projeção DRE'!F13 -> 19.171 | E4: ='Projeção DRE'!G13 -> 103.23 | F4: ='Projeção DRE'!H13 -> 38.323 | G4: ='Projeção DRE'!I13 -> 30.123 | H4: ='Projeção DRE'!J13 -> 43.628 | I4: ='Projeção DRE'!K13 -> 38.793514 | J4: ='Projeção DRE'!L13 -> 40.082095 | ... R4: ='Projeção DRE'!T13 -> 39.526854
B5: IR + CSLL (sob o LAIR) | I5: ='Projeção DRE'!K20 -> 9.6824168 | J5: ='Projeção DRE'!L20 -> 8.4566592 | K5: ='Projeção DRE'!M20 -> 7.4555791 | L5: ='Projeção DRE'!N20 -> 6.6379938 | M5: ='Projeção DRE'!O20 -> 5.9702692 | N5: ='Projeção DRE'!P20 -> 5.4249365 | O5: ='Projeção DRE'!Q20 -> 4.9795616 | P5: ='Projeção DRE'!R20 -> 4.6158225 | ... R5: ='Projeção DRE'!T20 -> 4.0761401
B6: Alíquota IR + CSLL (sob o LAIR) | I6: ='Projeção DRE'!K20/'Projeção DRE'!K19 -> 0.1542555 | J6: ='Projeção DRE'!L20/'Projeção DRE'!L19 -> 0.13896139 | K6: ='Projeção DRE'!M20/'Projeção DRE'!M19 -> 0.12760117 | L6: ='Projeção DRE'!N20/'Projeção DRE'!N19 -> 0.11759072 | M6: ='Projeção DRE'!O20/'Projeção DRE'!O19 -> 0.10909681 | N6: ='Projeção DRE'!P20/'Projeção DRE'!P19 -> 0.10221818 | O6: ='Projeção DRE'!Q20/'Projeção DRE'!Q19 -> 0.096964679 | P6: ='Projeção DRE'!R20/'Projeção DRE'!R19 -> 0.093351637 | ... R6: ='Projeção DRE'!T20/'Projeção DRE'!T19 -> 0.091240859
B7: WACC | H7: 0.151 | I7: ='ESTRUTURA DE CAPITAL'!L31 -> 0.14481113 | J7: =I7 -> 0.14481113 | K7: =J7 -> 0.14481113 | L7: =K7 -> 0.14481113 | M7: =L7 -> 0.14481113 | N7: =M7 -> 0.14481113 | O7: =N7 -> 0.14481113 | P7: =O7 -> 0.14481113 | Q7: =P7 -> 0.14481113 | R7: =Q7 -> 0.14481113
B8: ROIC | C8: =DADOS!H34 -> 0.13317376 | D8: =DADOS!I34 -> 0.10309162 | E8: =DADOS!J34 -> 0.58248225 | F8: =DADOS!K34 -> 0.1407143 | G8: =DADOS!L34 -> 0.10489161 | H8: =DADOS!M34 -> 0.12291538 | I8: =I14/H12 -> 0.10332661 | J8: =J14/I12 -> 0.10868933 | K8: =K14/J12 -> 0.11326599 | L8: =L14/K12 -> 0.11717198 | M8: =M14/L12 -> 0.12014197 | N8: =N14/M12 -> 0.12189803 | O8: =O14/N12 -> 0.12224451 | P8: =P14/O12 -> 0.12098799 | ... R8: =R14/Q12 -> 0.11312404
B9: b | C9: =DADOS!H36 -> -0.12187899 | D9: =DADOS!I36 -> -0.025125684 | E9: =DADOS!J36 -> 0.79188735 | F9: =DADOS!K36 -> 0.31173938 | G9: =DADOS!L36 -> 0.41362324 | H9: =DADOS!M36 -> 1.4228647 | I9: 0 | J9: 0 | K9: 0 | L9: 0 | M9: 0 | N9: 0 | O9: 0 | P9: 0 | Q9: 0 | R9: 0 | XFA9: \
B10: g | C10: =C8*C9 -> -0.016231083 | D10: =D8*D9 -> -0.0025902475 | E10: =E8*E9 -> 0.46126033 | F10: =F8*F9 -> 0.043866189 | G10: =G8*G9 -> 0.043385606 | H10: =H8*H9 -> 0.17489196 | I10: =I8*I9 -> 0 | J10: =J8*J9 -> 0 | ... R10: =R8*R9 -> 0
B12: Capital Investido | C12: =DADOS!H19 -> 170.254 | D12: =DADOS!I19 -> 169.813 | E12: =DADOS!J19 -> 248.141 | F12: =DADOS!K19 -> 259.026 | G12: =DADOS!L19 -> 270.264 | H12: =DADOS!M19 -> 317.531 | I12: =H12-I16 -> 317.531 | J12: =I12-J16 -> 317.531 | K12: =J12-K16 -> 317.531 | L12: =K12-L16 -> 317.531 | M12: =L12-M16 -> 317.531 | N12: =M12-N16 -> 317.531 | O12: =N12-O16 -> 317.531 | P12: =O12-P16 -> 317.531 | ... R12: =Q12-R16 -> 317.531
A14: (+) | B14: NOPAT [(LAJIR *(1 - IR)] | C14: =DADOS!H28 -> 23.047451 | D14: =DADOS!I28 -> 17.551761 | E14: =DADOS!J28 -> 98.913059 | F14: =DADOS!K28 -> 34.916987 | G14: =DADOS!L28 -> 27.169653 | H14: =DADOS!M28 -> 33.219602 | I14: =I4*(1-I6) -> 32.809401 | J14: =J4*(1-J6) -> 34.512232 | K14: =K4*(1-K6) -> 35.965463 | L14: =L4*(1-L6) -> 37.205737 | M14: =M4*(1-M6) -> 38.148801 | N14: =N4*(1-N6) -> 38.706403 | O14: =O4*(1-O6) -> 38.81642 | P14: =P4*(1-P6) -> 38.417439 | ... R14: =R4*(1-R6) -> 35.92039
A15: (+) | B15: NOPAT (CAP. INV. * ROIC) | C15: =DADOS!H28 -> 23.047451 | D15: =DADOS!I28 -> 17.551761 | E15: =DADOS!J28 -> 98.913059 | F15: =DADOS!K28 -> 34.916987 | G15: =DADOS!L28 -> 27.169653 | H15: =DADOS!M28 -> 33.219602 | I15: =I8*H12 -> 32.809401 | J15: =J8*I12 -> 34.512232 | K15: =K8*J12 -> 35.965463 | L15: =L8*K12 -> 37.205737 | M15: =M8*L12 -> 38.148801 | N15: =N8*M12 -> 38.706403 | O15: =O8*N12 -> 38.81642 | P15: =P8*O12 -> 38.417439 | ... R15: =R8*Q12 -> 35.92039
A16: (-) | B16: Invest.Líquido | C16: =DADOS!H21 -> 2.809 | D16: =DADOS!I21 -> 0.441 | E16: =DADOS!J21 -> -78.328 | F16: =DADOS!K21 -> -10.885 | G16: =DADOS!L21 -> -11.238 | H16: =DADOS!M21 -> -47.267 | I16: =-(I15*I9) -> 0 | J16: =-(J15*J9) -> 0 | K16: =-(K15*K9) -> 0 | L16: =-(L15*L9) -> 0 | M16: =-(M15*M9) -> 0 | N16: =-(N15*N9) -> 0 | O16: =-(O15*O9) -> 0 | P16: =-(P15*P9) -> 0 | ... R16: =-(R15*R9) -> 0
A17: (=) | B17: Fluxo de Caixa Livre (FCLE) | C17: =SUM(C15:C16) -> 25.856451 | D17: =SUM(D15:D16) -> 17.992761 | E17: =SUM(E15:E16) -> 20.585059 | F17: =SUM(F15:F16) -> 24.031987 | G17: =SUM(G15:G16) -> 15.931653 | H17: =SUM(H15:H16) -> -14.047398 | I17: =SUM(I15:I16) -> 32.809401 | J17: =SUM(J15:J16) -> 34.512232 | ... R17: =SUM(R15:R16) -> 35.92039
A19: Valor da Empresa (histórico) | C19: =#REF! -> #REF! | D19: 591.5481 | E19: 542.482 | F19: 563.803 | G19: 539.0982 | H19: 474.5308
R20: Perpetuidade:
A21: Valor Residual | R21: =R17*(1+R10)/(R7-R10) -> 248.04993
A22: Fluxo Caixa | E22: =E17+E21 -> 20.585059 | F22: =F17+F21 -> 24.031987 | G22: =G17+G21 -> 15.931653 | H22: =H17+H21 -> -14.047398 | I22: =I17+I21 -> 32.809401 | J22: =J17+J21 -> 34.512232 | K22: =K17+K21 -> 35.965463 | L22: =L17+L21 -> 37.205737 | ... R22: =R17+R21 -> 283.97032
A24: Fator de Desconto (Taxa "r") | H24: 1 | I24: =(1+I7)^(-(I1-$H$1)) -> 0.87350653 | J24: =(1+J7)^(-(J1-$H$1)) -> 0.76301367 | K24: =(1+K7)^(-(K1-$H$1)) -> 0.66649742 | L24: =(1+L7)^(-(L1-$H$1)) -> 0.58218985 | M24: =(1+M7)^(-(M1-$H$1)) -> 0.50854664 | N24: =(1+N7)^(-(N1-$H$1)) -> 0.44421882 | O24: =(1+O7)^(-(O1-$H$1)) -> 0.38802804 | P24: =(1+P7)^(-(P1-$H$1)) -> 0.33894503 | ... R24: =(1+R7)^(-(R1-$H$1)) -> 0.25861969
A26: Fluxos de Caixa à Valor Presente | H26: =SUMPRODUCT(I22:$R22,I24:$R24)/H24 -> 249.83571 | I26: =SUMPRODUCT(J22:$R22,J24:$R24)/I24 -> 253.2053 | J26: =SUMPRODUCT(K22:$R22,K24:$R24)/J24 -> 255.36001 | K26: =SUMPRODUCT(L22:$R22,L24:$R24)/K24 -> 256.37352 | L26: =SUMPRODUCT(M22:$R22,M24:$R24)/L24 -> 256.29352 | M26: =SUMPRODUCT(N22:$R22,N24:$R24)/M24 -> 255.25887 | N26: =SUMPRODUCT(O22:$R22,O24:$R24)/N24 -> 253.51679 | O26: =SUMPRODUCT(P22:$R22,P24:$R24)/O24 -> 251.41242 | ... Q26: =SUMPRODUCT(R22:$R22,R24:$R24)/Q24 -> 248.04993 | R26: =R21 -> 248.04993
A27: Crescimento do Valor da Empresa | I27: =I26/H26-1 -> 0.01348722 | J27: =J26/I26-1 -> 0.0085097451 | K27: =K26/J26-1 -> 0.0039689379 | L27: =L26/K26-1 -> -0.00031204246 | M27: =M26/L26-1 -> -0.0040369634 | N27: =N26/M26-1 -> -0.0068247534 | O27: =O26/N26-1 -> -0.0083007048 | P27: =P26/O26-1 -> -0.0079953183 | ... R27: =R26/Q26-1 -> 0
A30: Lucro Econômico | I30: =H12*(I8-I7) -> -13.172621 | J30: =I12*(J8-J7) -> -11.46979 | K30: =J12*(K8-K7) -> -10.016559 | L30: =K12*(L8-L7) -> -8.7762846 | M30: =L12*(M8-M7) -> -7.8332213 | N30: =M12*(N8-N7) -> -7.2756184 | O30: =N12*(O8-O7) -> -7.1656016 | P30: =O12*(P8-P7) -> -7.5645832 | ... R30: =Q12*(R8-R7) -> -10.061632
A31: Valor Residual(LE) | R31: =R30*(1+R10)/(R7-R10) -> -69.481068
A33: VP(LE) | H33: =(SUMPRODUCT(I30:$R30,I24:$R24)+$R$31*$R$24)/H24 -> -67.695293 | I33: =(SUMPRODUCT(J30:$R30,J24:$R24)+$R$31*$R$24)/I24 -> -64.325703 | J33: =(SUMPRODUCT(K30:$R30,K24:$R24)+$R$31*$R$24)/J24 -> -62.170991 | K33: =(SUMPRODUCT(L30:$R30,L24:$R24)+$R$31*$R$24)/K24 -> -61.157483 | L33: =(SUMPRODUCT(M30:$R30,M24:$R24)+$R$31*$R$24)/L24 -> -61.237482 | M33: =(SUMPRODUCT(N30:$R30,N24:$R24)+$R$31*$R$24)/M24 -> -62.27213 | N33: =(SUMPRODUCT(O30:$R30,O24:$R24)+$R$31*$R$24)/N24 -> -64.014209 | O33: =(SUMPRODUCT(P30:$R30,P24:$R24)+$R$31*$R$24)/O24 -> -66.118577 | ... Q33: =(SUMPRODUCT(R30:$R30,R24:$R24)+$R$31*$R$24)/Q24 -> -69.481068 | R33: =(SUMPRODUCT($R30:$R30,$R24:$R24)+$R$31*$R$24)/R24 -> -79.5427
A34: Capital Investido | H34: =H12 -> 317.531 | I34: =I12 -> 317.531 | J34: =J12 -> 317.531 | K34: =K12 -> 317.531 | L34: =L12 -> 317.531 | M34: =M12 -> 317.531 | N34: =N12 -> 317.531 | O34: =O12 -> 317.531 | ... R34: =R12 -> 317.531
A35: Valor Econômico da Empresa Projetado | H35: =SUM(H33:H34) -> 249.83571 | I35: =SUM(I33:I34) -> 253.2053 | J35: =SUM(J33:J34) -> 255.36001 | K35: =SUM(K33:K34) -> 256.37352 | L35: =SUM(L33:L34) -> 256.29352 | M35: =SUM(M33:M34) -> 255.25887 | N35: =SUM(N33:N34) -> 253.51679 | O35: =SUM(O33:O34) -> 251.41242 | ... R35: =SUM(R33:R34) -> 237.9883
A37: Valor Total da Empresa Projetado | H37: =I35*(10^6) -> 2.532053e+08
A38: Dívida Total da Empresa | H38: =SUM(DADOS!M16:M17)*(10^6) -> 64619000
A39: PL / Market Captalization | H39: =H37-H38 -> 1.885863e+08
A40: QTD de ações ordinárias da empresa | H40: 63084700
A41: Valor por ação | H41: =H39/H40 -> 2.9894142

Sheet Aval. Valor Patrimonial da Ação
B1: Baseado no Valor Patrimonial por Ação da Afluente T em 30 de setembro de 2025
B3: CÁLCULO DO VALOR PATRIMONIAL
B4: Patrimônio Líquido Total | C4: 255393000
B5: QTD de ações ordinárias | C5: ='Aval. Fluxo de Caixa Descontado'!H40 -> 63084700
B6: Valor patrimonial por ação | C6: =C4/C5 -> 4.0484143
B9: CÁLCULO DO PREÇO POR VALOR PATRIMONIAL (P/VPA)
B10: Preço da ação no dia 30/10/2025 | C10: 7.22
B11: Valor patrimonial por ação | C11: =C4/C5 -> 4.0484143
B12: Preço/Valor Patrimonial | C12: =C10/C11 -> 1.7834143
B14: *O mercado estava pagando 1,78x o valor patrimonial da ação no dia 30/10/2025, apresentando assim uma boa expectativa em relação ao título.

Sheet Aval. VWAP
O1: Price Buckets | P1: Trades | Q1: Volume | R1: Bid | S1: Mid | T1: Ask | V1: PERÍODO
O2: 7.98 | P2: 4 | Q2: 700 | R2: 0 | S2: 0 | T2: 700 | V2: 04/11/24 até 30/10/25
B3: CÁLCULO DO PREÇO MÉDIO POR VOLUME NEGOCIADO (VWAP) | O3: 7.8 | P3: 36 | Q3: 3600 | R3: 0 | S3: 0 | T3: 3600
B4: Período: 04/11/24 até 30/10/25 | O4: 7.79 | P4: 5 | Q4: 800 | R4: 200 | S4: 100 | T4: 500
B5: Preço médio por volume negoc. | C5: =(SUMPRODUCT(O2:O95,Q2:Q95))/Q96 -> 7.2103614 | O5: 7.77 | P5: 2 | Q5: 200 | R5: 0 | S5: 0 | T5: 200
O6: 7.75 | P6: 5 | Q6: 700 | R6: 200 | S6: 400 | T6: 100
O7: 7.74 | P7: 2 | Q7: 100 | R7: 0 | S7: 0 | T7: 100
O8: 7.73 | P8: 2 | Q8: 100 | R8: 0 | S8: 0 | T8: 100
O9: 7.7 | P9: 1 | Q9: 100 | R9: 0 | S9: 0 | T9: 100
O10: 7.69 | P10: 3 | Q10: 200 | R10: 0 | S10: 100 | T10: 100
O11: 7.68 | P11: 3 | Q11: 400 | R11: 100 | S11: 200 | T11: 100
O12: 7.67 | P12: 3 | Q12: 300 | R12: 0 | S12: 0 | T12: 300
O13: 7.66 | P13: 3 | Q13: 300 | R13: 0 | S13: 100 | T13: 200
O14: 7.65 | P14: 1 | Q14: 100 | R14: 0 | S14: 0 | T14: 100
O15: 7.63 | P15: 3 | Q15: 400 | R15: 0 | S15: 400 | T15: 0
O16: 7.6 | P16: 5 | Q16: 600 | R16: 0 | S16: 100 | T16: 500
O17: 7.59 | P17: 6 | Q17: 900 | R17: 0 | S17: 0 | T17: 900
... O95: 6.53 | P95: 4 | Q95: 200 | R95: 200 | S95: 0 | T95: 0
O96: Totals | P96: 480 | Q96: 66400 | R96: 28300 | S96: 15000 | T96: 23100

Sheet Projeção DRE
A1: Em Milhões de BRL exceto Por ação
A2: Ano | B2: 2016 | C2: 2017 | D2: 2018 | E2: 2019 | F2: 2020 | G2: 2021 | H2: 2022 | I2: 2023 | J2: 2024 | K2: 2025 | L2: 2026 | M2: 2027 | N2: 2028 | O2: 2029 | P2: 2030 | Q2: 2031 | R2: 2032 | S2: 2033 | T2: 2034
A3: Receita | B3: 31.353 | C3: 23.646 | D3: 33.684 | E3: 38.621 | F3: 35.93 | G3: 120.319 | H3: 72.058 | I3: 67.307 | J3: 85.999 | K3: ='Proj. Receita e MG Operacional'!H55 -> 81.447 | L3: ='Proj. Receita e MG Operacional'!I55 -> 86.813486 | M3: ='Proj. Receita e MG Operacional'!J55 -> 92.03559 | N3: ='Proj. Receita e MG Operacional'!K55 -> 97.043889 | O3: ='Proj. Receita e MG Operacional'!L55 -> 101.76806 | P3: ='Proj. Receita e MG Operacional'!M55 -> 106.13846 | Q3: ='Proj. Receita e MG Operacional'!N55 -> 110.08771 | R3: ='Proj. Receita e MG Operacional'!O55 -> 113.55243 | ... T3: ='Proj. Receita e MG Operacional'!Q55 -> 118.80433
A4: Custo de bens e serviços | B4: 14.175 | C4: 10.425 | D4: 10.028 | E4: 13.006 | F4: 12.631 | G4: 13.665 | H4: 27.45 | I4: 32.273 | J4: 38.034 | K4: ='Proj. Custos da receita'!B25 -> 35.449917 | L4: ='Proj. Custos da receita'!C25 -> 38.724633 | M4: ='Proj. Custos da receita'!D25 -> 41.99935 | N4: ='Proj. Custos da receita'!E25 -> 45.274067 | O4: ='Proj. Custos da receita'!F25 -> 48.548783 | P4: ='Proj. Custos da receita'!G25 -> 51.8235 | Q4: ='Proj. Custos da receita'!H25 -> 55.098217 | R4: ='Proj. Custos da receita'!I25 -> 58.372933 | ... T4: ='Proj. Custos da receita'!K25 -> 64.922367
A5: Depreciação e amortização: | B5: 0 | C5: 0 | D5: 0 | E5: 0 | F5: 0 | G5: 0 | H5: 0.06 | I5: 0.045 | J5: 0.057 | K5: ='Proj. Custos da receita'!B26 -> 0.057954961 | L5: ='Proj. Custos da receita'!C26 -> 0.065945953 | M5: ='Proj. Custos da receita'!D26 -> 0.073936945 | N5: ='Proj. Custos da receita'!E26 -> 0.081927937 | O5: ='Proj. Custos da receita'!F26 -> 0.089918929 | P5: ='Proj. Custos da receita'!G26 -> 0.097909922 | Q5: ='Proj. Custos da receita'!H26 -> 0.10590091 | R5: ='Proj. Custos da receita'!I26 -> 0.11389191 | ... T5: ='Proj. Custos da receita'!K26 -> 0.12987389
A6: Lucro bruto | B6: 17.178 | C6: 13.221 | D6: 23.656 | E6: 25.615 | F6: 23.299 | G6: 106.654 | H6: 44.548 | I6: 34.989 | J6: =J3-SUM(J4:J5) -> 47.908 | K6: =K3-SUM(K4:K5) -> 45.939128 | L6: =L3-SUM(L4:L5) -> 48.022907 | M6: =M3-SUM(M4:M5) -> 49.962303 | N6: =N3-SUM(N4:N5) -> 51.687894 | O6: =O3-SUM(O4:O5) -> 53.129362 | P6: =P3-SUM(P4:P5) -> 54.217049 | Q6: =Q3-SUM(Q4:Q5) -> 54.883593 | ... T6: =T3-SUM(T4:T5) -> 53.752086
A7: Outros lucros operacionais | B7: 0 | C7: 0 | D7: 0 | E7: 0 | F7: 0 | G7: 0.005 | H7: 0 | I7: 0 | J7: 0.109 | K7: =AVERAGE(B7:J7) -> 0.012666667 | L7: =AVERAGE(C7:K7) -> 0.014074074 | M7: =AVERAGE(D7:L7) -> 0.01563786 | N7: =AVERAGE(E7:M7) -> 0.0173754 | O7: =AVERAGE(F7:N7) -> 0.019306 | P7: =AVERAGE(G7:O7) -> 0.021451111 | Q7: =AVERAGE(H7:P7) -> 0.023279012 | R7: =AVERAGE(I7:Q7) -> 0.025865569 | ... T7: =AVERAGE(K7:S7) -> 0.019821691
A8: Despesas operacionais | B8: 0.779 | C8: 0.555 | D8: 0.753 | E8: 0.654 | F8: 4.128 | G8: 3.429 | H8: 6.225 | I8: 4.866 | J8: =SUM(J9:J12) -> 4.993 | K8: =SUM(K9:K12) -> 7.1582811 | L8: =SUM(L9:L12) -> 7.9548855 | M8: =SUM(M9:M12) -> 8.7520001 | N8: =SUM(N9:N12) -> 9.5414595 | O8: =SUM(O9:O12) -> 10.328302 | P8: =SUM(P9:P12) -> 11.125126 | Q8: =SUM(Q9:Q12) -> 11.922484 | ... T8: =SUM(T9:T12) -> 14.245054
A9: Venda e marketing | B9: 0 | C9: 0 | D9: 0.074 | E9: 0.095 | F9: 0 | G9: 0 | H9: 0.018 | I9: 0.185 | J9: 0 | K9: ='Proj. Despesas Operacionais'!B23 -> 0.041333333 | L9: ='Proj. Despesas Operacionais'!C23 -> 0.045925926 | M9: ='Proj. Despesas Operacionais'!D23 -> 0.051028807 | N9: ='Proj. Despesas Operacionais'!E23 -> 0.048476452 | O9: ='Proj. Despesas Operacionais'!F23 -> 0.043307169 | P9: ='Proj. Despesas Operacionais'!G23 -> 0.048119076 | Q9: ='Proj. Despesas Operacionais'!H23 -> 0.05346564 | R9: ='Proj. Despesas Operacionais'!I23 -> 0.057406267 | S9: ='Proj. Despesas Operacionais'!J23 -> 0.043229186 | T9: ='Proj. Despesas Operacionais'!K24 -> 12.625078
A10: Geral e administrativas | B10: 0 | C10: 0.555 | D10: 0.679 | E10: 0.559 | F10: 4.202 | G10: 3.365 | H10: 6.094 | I10: 4.528 | J10: 4.253 | K10: ='Proj. Despesas Operacionais'!B24 -> 6.2400278 | L10: ='Proj. Despesas Operacionais'!C24 -> 6.9494778 | M10: ='Proj. Despesas Operacionais'!D24 -> 7.6589278 | N10: ='Proj. Despesas Operacionais'!E24 -> 8.3683778 | O10: ='Proj. Despesas Operacionais'!F24 -> 9.0778278 | P10: ='Proj. Despesas Operacionais'!G24 -> 9.7872778 | Q10: ='Proj. Despesas Operacionais'!H24 -> 10.496728 | R10: ='Proj. Despesas Operacionais'!I24 -> 11.206178 | S10: ='Proj. Despesas Operacionais'!J24 -> 11.915628 | T10: ='Proj. Despesas Operacionais'!K25 -> 1.3011
A11: Pesquisa e desenvolvimento (Outras desp operacionais) | B11: 0 | C11: 0.334 | D11: 0.355 | E11: 0.393 | F11: 0.38 | G11: 0.449 | H11: 0.539 | I11: 0.657 | J11: 0.604 | K11: ='Proj. Despesas Operacionais'!B25 -> 0.72975 | L11: ='Proj. Despesas Operacionais'!C25 -> 0.79323333 | M11: ='Proj. Despesas Operacionais'!D25 -> 0.85671667 | N11: ='Proj. Despesas Operacionais'!E25 -> 0.9202 | O11: ='Proj. Despesas Operacionais'!F25 -> 0.98368333 | P11: ='Proj. Despesas Operacionais'!G25 -> 1.0471667 | Q11: ='Proj. Despesas Operacionais'!H25 -> 1.11065 | R11: ='Proj. Despesas Operacionais'!I25 -> 1.1741333 | S11: ='Proj. Despesas Operacionais'!J25 -> 1.2376167 | T11: ='Proj. Despesas Operacionais'!K26 -> 0.31887595
A12: Depreciação e amortização | B12: 0 | C12: 0 | D12: 0 | E12: 0 | F12: 0 | G12: 0.064 | H12: 0.113 | I12: 0.153 | J12: 0.136 | K12: ='Proj. Despesas Operacionais'!B26 -> 0.14716998 | L12: ='Proj. Despesas Operacionais'!C26 -> 0.16624842 | M12: ='Proj. Despesas Operacionais'!D26 -> 0.18532686 | N12: ='Proj. Despesas Operacionais'!E26 -> 0.2044053 | O12: ='Proj. Despesas Operacionais'!F26 -> 0.22348375 | P12: ='Proj. Despesas Operacionais'!G26 -> 0.24256219 | Q12: ='Proj. Despesas Operacionais'!H26 -> 0.26164063 | R12: ='Proj. Despesas Operacionais'!I26 -> 0.28071907 | S12: ='Proj. Despesas Operacionais'!J26 -> 0.29979751 | T12: ='Proj. Despesas Operacionais'!K27 -> 0
A13: Lucro (Prejuízo) operacional (EBIT/LAJIR) | B13: 16.399 | C13: 12.666 | D13: 22.903 | E13: 24.961 | F13: 19.171 | G13: 103.23 | H13: 38.323 | I13: 30.123 | J13: 43.628 | K13: =K6+K7-K8 -> 38.793514 | L13: =L6+L7-L8 -> 40.082095 | M13: =M6+M7-M8 -> 41.225941 | N13: =N6+N7-N8 -> 42.16381 | O13: =O6+O7-O8 -> 42.820366 | P13: =P6+P7-P8 -> 43.113374 | Q13: =Q6+Q7-Q8 -> 42.984388 | R13: =R6+R7-R8 -> 42.37303 | ... T13: =T6+T7-T8 -> 39.526854
A14: Perdas (lucros) não operacionais | B14: =B17+(SUM(B16,B18)) -> -5.26 | C14: =C17+(SUM(C16,C18)) -> -2.278 | D14: =D17+(SUM(D16,D18)) -> -1.402 | E14: =E17+(SUM(E16,E18)) -> -2.393 | F14: =F17+(SUM(F16,F18)) -> -1.264 | G14: =G17+(SUM(G16,G18)) -> -0.934 | H14: =H17+(SUM(H16,H18)) -> -2.824 | I14: =I17+(SUM(I16,I18)) -> -1.71 | ... T14: =T17+(SUM(T16,T18)) -> -5.1499341
A15: Despesa de juros, líq | B15: -5.26 | C15: -2.429 | D15: -1.491 | E15: -2.349 | F15: -1.403 | G15: -0.938 | H15: -2.908 | I15: -1.434 | J15: -1.64 | K15: ='Proj. Despesa não operacional'!B57 -> -23.979668 | L15: ='Proj. Despesa não operacional'!C57 -> -20.778716 | M15: ='Proj. Despesa não operacional'!D57 -> -17.207592 | N15: ='Proj. Despesa não operacional'!E57 -> -14.291044 | O15: ='Proj. Despesa não operacional'!F57 -> -11.90909 | P15: ='Proj. Despesa não operacional'!G57 -> -9.9637409 | Q15: ='Proj. Despesa não operacional'!H57 -> -8.3749679 | R15: ='Proj. Despesa não operacional'!I57 -> -7.0774119 | ... T15: ='Proj. Despesa não operacional'!K57 -> -5.1522188
A16: Despesa com juros | B16: 0.192 | C16: 0.157 | D16: 0.121 | E16: 0.086 | F16: 0.053 | G16: 0.037 | H16: 0.025 | I16: 0.014 | J16: 0.105 | K16: ='Proj. Despesa não operacional'!B58 -> 1.3984489 | L16: ='Proj. Despesa não operacional'!C58 -> 1.2057688 | M16: ='Proj. Despesa não operacional'!D58 -> 0.99080637 | N16: ='Proj. Despesa não operacional'!E58 -> 0.81524585 | O16: ='Proj. Despesa não operacional'!F58 -> 0.67186502 | P16: ='Proj. Despesa não operacional'!G58 -> 0.55476545 | Q16: ='Proj. Despesa não operacional'!H58 -> 0.45912986 | R16: ='Proj. Despesa não operacional'!I58 -> 0.38102396 | ... T16: ='Proj. Despesa não operacional'!K58 -> 0.26513769
A17: Lucro com juros | B17: =B15-B16 -> -5.452 | C17: =C15-C16 -> -2.586 | D17: =D15-D16 -> -1.612 | E17: =E15-E16 -> -2.435 | F17: =F15-F16 -> -1.456 | G17: =G15-G16 -> -0.975 | H17: =H15-H16 -> -2.933 | I17: =I15-I16 -> -1.448 | ... T17: =T15-T16 -> -5.4173565
A18: Outros Prejuízos (Lucros) não op | B18: 0 | C18: 0.151 | D18: 0.089 | E18: -0.044 | F18: 0.139 | G18: 0.004 | H18: 0.084 | I18: -0.276 | J18: -0.129 | K18: =K13*'Proj. Despesa não operacional'!B59 -> 0.0022423708 | L18: =L13*'Proj. Despesa não operacional'!C59 -> 0.0023168544 | M18: =M13*'Proj. Despesa não operacional'!D59 -> 0.0023829718 | N18: =N13*'Proj. Despesa não operacional'!E59 -> 0.0024371831 | O18: =O13*'Proj. Despesa não operacional'!F59 -> 0.0024751339 | P18: =P13*'Proj. Despesa não operacional'!G59 -> 0.0024920705 | Q18: =Q13*'Proj. Despesa não operacional'!H59 -> 0.0024846148 | R18: =R13*'Proj. Despesa não operacional'!I59 -> 0.0024492767 | ... T18: =T13*'Proj. Despesa não operacional'!K59 -> 0.0022847599
A19: Lucro (Prejuízo) antes de impostos (LAIR) | B19: 21.237 | C19: 14.944 | D19: 24.305 | E19: 27.354 | F19: 20.435 | G19: 104.164 | H19: 41.147 | I19: 31.833 | J19: =J13-J14-J18 -> 45.526 | K19: =K13-K14-K18 -> 62.768697 | L19: =L13-L14-L18 -> 60.856178 | M19: =M13-M14-M18 -> 58.428767 | N19: =N13-N14-N18 -> 56.44998 | O19: =O13-O14-O18 -> 54.724506 | P19: =P13-P14-P18 -> 53.072131 | Q19: =Q13-Q14-Q18 -> 51.354386 | ... T19: =T13-T14-T18 -> 44.674504
A20: Desp c/imposto renda (Benefício) | B20: 6.949 | C20: 2.427 | D20: 1.689 | E20: 2.097 | F20: 1.726 | G20: 4.356 | H20: 3.657 | I20: 3.121 | J20: 10.662 | K20: ='Proj. Imposto de Renda'!B28 -> 9.6824168 | L20: ='Proj. Imposto de Renda'!C28 -> 8.4566592 | M20: ='Proj. Imposto de Renda'!D28 -> 7.4555791 | N20: ='Proj. Imposto de Renda'!E28 -> 6.6379938 | O20: ='Proj. Imposto de Renda'!F28 -> 5.9702692 | P20: ='Proj. Imposto de Renda'!G28 -> 5.4249365 | Q20: ='Proj. Imposto de Renda'!H28 -> 4.9795616 | R20: ='Proj. Imposto de Renda'!I28 -> 4.6158225 | ... T20: ='Proj. Imposto de Renda'!K28 -> 4.0761401
A21: Lucro líquido, GAAP | B21: =B19-B20 -> 14.288 | C21: =C19-C20 -> 12.517 | D21: =D19-D20 -> 22.616 | E21: =E19-E20 -> 25.257 | F21: =F19-F20 -> 18.709 | G21: =G19-G20 -> 99.808 | H21: =H19-H20 -> 37.49 | I21: =I19-I20 -> 28.712 | ... T21: =T19-T20 -> 40.598363
A23: EBITDA/LAJIDA | B23: =B13+B12+B5 -> 16.399 | C23: =C13+C12+C5 -> 12.666 | D23: =D13+D12+D5 -> 22.903 | E23: =E13+E12+E5 -> 24.961 | F23: =F13+F12+F5 -> 19.171 | G23: =G13+G12+G5 -> 103.294 | H23: =H13+H12+H5 -> 38.496 | I23: =I13+I12+I5 -> 30.321 | ... T23: =T13+T12+T5 -> 39.656728
A24: Mg EBITDA/LAJIDA | B24: =B23/B3 -> 0.52304405 | C24: =C23/C3 -> 0.53565085 | D24: =D23/D3 -> 0.67993706 | E24: =E23/E3 -> 0.64630641 | F24: =F23/F3 -> 0.53356527 | G24: =G23/G3 -> 0.85850115 | H24: =H23/H3 -> 0.53423631 | I24: =I23/I3 -> 0.45048806 | ... T24: =T23/T3 -> 0.33379869
A25: EBIT/LAJIR | B25: =B13 -> 16.399 | C25: =C13 -> 12.666 | D25: =D13 -> 22.903 | E25: =E13 -> 24.961 | F25: =F13 -> 19.171 | G25: =G13 -> 103.23 | H25: =H13 -> 38.323 | I25: =I13 -> 30.123 | ... T25: =T13 -> 39.526854
A26: Mg EBIT/LAJIR | B26: =B25/B3 -> 0.52304405 | C26: =C25/C3 -> 0.53565085 | D26: =D25/D3 -> 0.67993706 | E26: =E25/E3 -> 0.64630641 | F26: =F25/F3 -> 0.53356527 | G26: =G25/G3 -> 0.85796923 | H26: =H25/H3 -> 0.53183547 | I26: =I25/I3 -> 0.44754632 | ... T26: =T25/T3 -> 0.33270551
A27: Margem bruta | B27: =B6/B3 -> 0.54789015 | C27: =C6/C3 -> 0.55912205 | D27: =D6/D3 -> 0.70229189 | E27: =E6/E3 -> 0.66324021 | F27: =F6/F3 -> 0.64845533 | G27: =G6/G3 -> 0.88642692 | H27: =H6/H3 -> 0.61822421 | I27: =I6/I3 -> 0.51984192 | ... T27: =T6/T3 -> 0.45244216
A28: Margem operacional | B28: =B13/B3 -> 0.52304405 | C28: =C13/C3 -> 0.53565085 | D28: =D13/D3 -> 0.67993706 | E28: =E13/E3 -> 0.64630641 | F28: =F13/F3 -> 0.53356527 | G28: =G13/G3 -> 0.85796923 | H28: =H13/H3 -> 0.53183547 | I28: =I13/I3 -> 0.44754632 | ... T28: =T13/T3 -> 0.33270551
A29: Margem de lucro líquido (sob a receita) | B29: =B21/B3 -> 0.45571397 | C29: =C21/C3 -> 0.52934957 | D29: =D21/D3 -> 0.6714167 | E29: =E21/E3 -> 0.65397064 | F29: =F21/F3 -> 0.52070693 | G29: =G21/G3 -> 0.82952817 | H29: =H21/H3 -> 0.52027533 | I29: =I21/I3 -> 0.42658267 | ... T29: =T21/T3 -> 0.34172462
A30: Dívida Bruta | B30: ='Bal patrim - Padronizado'!D44+'Bal patrim - Padronizado'!D53 -> 3.434 | C30: ='Bal patrim - Padronizado'!E44+'Bal patrim - Padronizado'!E53 -> 2.705 | D30: ='Bal patrim - Padronizado'!F44+'Bal patrim - Padronizado'!F53 -> 1.976 | E30: ='Bal patrim - Padronizado'!G44+'Bal patrim - Padronizado'!G53 -> 1.248 | F30: ='Bal patrim - Padronizado'!H44+'Bal patrim - Padronizado'!H53 -> 0.739 | G30: ='Bal patrim - Padronizado'!I44+'Bal patrim - Padronizado'!I53 -> 0.537 | H30: ='Bal patrim - Padronizado'!J44+'Bal patrim - Padronizado'!J53 -> 0.336 | I30: ='Bal patrim - Padronizado'!K44+'Bal patrim - Padronizado'!K53 -> 0.134 | J30: ='Bal patrim - Padronizado'!L44+'Bal patrim - Padronizado'!L53 -> 30.794 | K30: ='Bal patrim B3 - 3º TRI 2025'!K58+'Bal patrim B3 - 3º TRI 2025'!K59 -> 27.422 | L30: ='Proj. Despesa não operacional'!L7+'Proj. Despesa não operacional'!L10 -> 22.391244 | M30: ='Proj. Despesa não operacional'!M7+'Proj. Despesa não operacional'!M10 -> 18.283433 | N30: ='Proj. Despesa não operacional'!N7+'Proj. Despesa não operacional'!N10 -> 14.929239 | O30: ='Proj. Despesa não operacional'!O7+'Proj. Despesa não operacional'!O10 -> 12.190402 | P30: ='Proj. Despesa não operacional'!P7+'Proj. Despesa não operacional'!P10 -> 9.9540261 | Q30: ='Proj. Despesa não operacional'!Q7+'Proj. Despesa não operacional'!Q10 -> 8.1279299 | R30: ='Proj. Despesa não operacional'!R7+'Proj. Despesa não operacional'!R10 -> 6.6368428 | S30: ='Proj. Despesa não operacional'!S7+'Proj. Despesa não operacional'!S10 -> 5.4193041 | T30: ='Proj. Despesa não operacional'!T7+'Proj. Despesa não operacional'!T10 -> 4.4251288
A31: CAIXA E EQUIVALENTES | B31: ='Bal patrim - Padronizado'!D7 -> 35.774 | C31: ='Bal patrim - Padronizado'!E7 -> 18.945 | D31: ='Bal patrim - Padronizado'!F7 -> 31.212 | E31: ='Bal patrim - Padronizado'!G7 -> 51.746 | F31: ='Bal patrim - Padronizado'!H7 -> 31.209 | G31: ='Bal patrim - Padronizado'!I7 -> 17.619 | H31: ='Bal patrim - Padronizado'!J7 -> 21.331 | I31: ='Bal patrim - Padronizado'!K7 -> 2.936 | J31: ='Bal patrim - Padronizado'!L7 -> 7.321 | K31: ='Bal patrim B3 - 3º TRI 2025 Atv'!E7 -> 38.09 | L31: - | M31: - | N31: - | O31: - | P31: - | Q31: - | R31: - | S31: - | T31: -
A32: Dívida Líquida | B32: =B30-B31 -> -32.34 | C32: =C30-C31 -> -16.24 | D32: =D30-D31 -> -29.236 | E32: =E30-E31 -> -50.498 | F32: =F30-F31 -> -30.47 | G32: =G30-G31 -> -17.082 | H32: =H30-H31 -> -20.995 | I32: =I30-I31 -> -2.802 | ... K32: =K30-K31 -> -10.668 | L32: - | M32: - | N32: - | O32: - | P32: - | Q32: - | R32: - | S32: - | T32: -
A33: Dívida Líquida/EBITDA | B33: =B32/B23 -> -1.9720715 | C33: =C32/C23 -> -1.2821727 | D33: =D32/D23 -> -1.276514 | E33: =E32/E23 -> -2.023076 | F33: =F32/F23 -> -1.5893798 | G33: =G32/G23 -> -0.16537263 | H33: =H32/H23 -> -0.54538134 | I33: =I32/I23 -> -0.0924112 | ... K33: =K32/K23 -> -0.27354801

Sheet Proj. Receita e MG Operacional
B1: ANO | C1: 2016 | D1: 2017 | E1: 2018 | F1: 2019 | G1: 2020 | H1: 2021 | I1: 2022 | J1: 2023 | K1: 2024 | L1: Últ 12M | T1: LAJIR (Lucro antes de Juros e Imposto de Renda)
B2: Receita | C2: 31.353 | D2: 23.646 | E2: 33.684 | F2: 38.621 | G2: 35.93 | H2: 120.319 | I2: 72.058 | J2: 67.307 | K2: 85.999 | L2: 81.447 | T2: "Causas X": RECEITA E ANO
B3: Lucro Bruto | C3: ='DRE - Ajustado 3º TRI 2025'!C11 -> 17.178 | D3: ='DRE - Ajustado 3º TRI 2025'!D11 -> 13.221 | E3: ='DRE - Ajustado 3º TRI 2025'!E11 -> 23.656 | F3: ='DRE - Ajustado 3º TRI 2025'!F11 -> 25.615 | G3: ='DRE - Ajustado 3º TRI 2025'!G11 -> 23.299 | H3: ='DRE - Ajustado 3º TRI 2025'!H11 -> 106.654 | I3: ='DRE - Ajustado 3º TRI 2025'!I11 -> 44.548 | J3: ='DRE - Ajustado 3º TRI 2025'!J11 -> 34.989 | ... L3: ='DRE - Ajustado 3º TRI 2025'!L11 -> 55.133 | T3: RESUMO DOS RESULTADOS - LAJIR: ANO;RECEITA
B4: LAJIR | C4: ='DRE - Ajustado 3º TRI 2025'!C20 -> 16.399 | D4: ='DRE - Ajustado 3º TRI 2025'!D20 -> 12.666 | E4: ='DRE - Ajustado 3º TRI 2025'!E20 -> 22.903 | F4: ='DRE - Ajustado 3º TRI 2025'!F20 -> 24.961 | G4: ='DRE - Ajustado 3º TRI 2025'!G20 -> 19.171 | H4: ='DRE - Ajustado 3º TRI 2025'!H20 -> 103.23 | I4: ='DRE - Ajustado 3º TRI 2025'!I20 -> 38.323 | J4: ='DRE - Ajustado 3º TRI 2025'!J20 -> 30.123 | ... L4: ='DRE - Ajustado 3º TRI 2025'!L20 -> 50.097
B5: IRPJ+CSLL | C5: ='DRE - Ajustado 3º TRI 2025'!C31/'DRE - Ajustado 3º TRI 2025'!C30 -> 0.32721194 | D5: ='DRE - Ajustado 3º TRI 2025'!D31/'DRE - Ajustado 3º TRI 2025'!D30 -> 0.16240632 | E5: ='DRE - Ajustado 3º TRI 2025'!E31/'DRE - Ajustado 3º TRI 2025'!E30 -> 0.069491874 | F5: ='DRE - Ajustado 3º TRI 2025'!F31/'DRE - Ajustado 3º TRI 2025'!F30 -> 0.076661549 | G5: ='DRE - Ajustado 3º TRI 2025'!G31/'DRE - Ajustado 3º TRI 2025'!G30 -> 0.084462931 | H5: ='DRE - Ajustado 3º TRI 2025'!H31/'DRE - Ajustado 3º TRI 2025'!H30 -> 0.041818671 | I5: ='DRE - Ajustado 3º TRI 2025'!I31/'DRE - Ajustado 3º TRI 2025'!I30 -> 0.088876467 | J5: ='DRE - Ajustado 3º TRI 2025'!J31/'DRE - Ajustado 3º TRI 2025'!J30 -> 0.098042911 | ... L5: ='DRE - Ajustado 3º TRI 2025'!L31/'DRE - Ajustado 3º TRI 2025'!L30 -> 0.29344521 | T5: Estatística de regressão
B6: NOPAT | C6: =C4*(1-C5) -> 11.033051 | D6: =D4*(1-D5) -> 10.608962 | E6: =E4*(1-E5) -> 21.311428 | F6: =F4*(1-F5) -> 23.047451 | G6: =G4*(1-G5) -> 17.551761 | H6: =H4*(1-H5) -> 98.913059 | I6: =I4*(1-I5) -> 34.916987 | J6: =J4*(1-J5) -> 27.169653 | ... L6: =L4*(1-L5) -> 35.396275 | T6: R múltiplo | U6: 0.97957378
T7: R-Quadrado | U7: 0.95956479
T8: R-quadrado ajustado | U8: 0.94801187
T9: Erro padrão | U9: 5.9409812
B10: A empresa tem apenas uma linha de negócio até a data do presente trabalho | T10: Observações | U10: 10
B11: ANO | C11: Receita | D11: Lucro Bruto | E11: LAJIR | F11: LAJIR ESPERADO | G11: MG operacional | H11: IRPJ+CSLL | I11: NOPAT
B12: 2016 | C12: 31.353 | D12: 17.178 | E12: 16.399 | F12: =$U$19+($U$20*B12)+($U$21*C12) -> 25.183041 | G12: =E12/C12 -> 0.52304405 | H12: ='DRE - Ajustado 3º TRI 2025'!C31/'DRE - Ajustado 3º TRI 2025'!C30 -> 0.32721194 | I12: =E12*(1-H12) -> 11.033051 | T12: ANOVA
B13: 2017 | C13: 23.646 | D13: 13.221 | E13: 12.666 | F13: =$U$19+($U$20*B13)+($U$21*C13) -> 12.695883 | G13: =E13/C13 -> 0.53565085 | H13: ='DRE - Ajustado 3º TRI 2025'!D31/'DRE - Ajustado 3º TRI 2025'!D30 -> 0.16240632 | I13: =E13*(1-H13) -> 10.608962 | U13: gl | V13: SQ | W13: MQ | X13: F | Y13: F de significação
B14: 2018 | C14: 33.684 | D14: 23.656 | E14: 22.903 | F14: =$U$19+($U$20*B14)+($U$21*C14) -> 19.113271 | G14: =E14/C14 -> 0.67993706 | H14: ='DRE - Ajustado 3º TRI 2025'!E31/'DRE - Ajustado 3º TRI 2025'!E30 -> 0.069491874 | I14: =E14*(1-H14) -> 21.311428 | T14: Regressão | U14: 2 | V14: 5863.1224 | W14: 2931.5612 | X14: 83.058219 | Y14: 1.3294104e-05
B15: 2019 | C15: 38.621 | D15: 25.615 | E15: 24.961 | F15: =$U$19+($U$20*B15)+($U$21*C15) -> 20.096335 | G15: =E15/C15 -> 0.64630641 | H15: ='DRE - Ajustado 3º TRI 2025'!F31/'DRE - Ajustado 3º TRI 2025'!F30 -> 0.076661549 | I15: =E15*(1-H15) -> 23.047451 | T15: Resíduo | U15: 7 | V15: 247.0668 | W15: 35.295257
B16: 2020 | C16: 35.93 | D16: 23.299 | E16: 19.171 | F16: =$U$19+($U$20*B16)+($U$21*C16) -> 12.952947 | G16: =E16/C16 -> 0.53356527 | H16: ='DRE - Ajustado 3º TRI 2025'!G31/'DRE - Ajustado 3º TRI 2025'!G30 -> 0.084462931 | I16: =E16*(1-H16) -> 17.551761 | T16: Total | U16: 9 | V16: 6110.1892
B17: 2021 | C17: 120.319 | D17: 106.654 | E17: 103.23 | F17: =$U$19+($U$20*B17)+($U$21*C17) -> 98.579798 | G17: =E17/C17 -> 0.85796923 | H17: ='DRE - Ajustado 3º TRI 2025'!H31/'DRE - Ajustado 3º TRI 2025'!H30 -> 0.041818671 | I17: =E17*(1-H17) -> 98.913059
B18: 2022 | C18: 72.058 | D18: 44.548 | E18: 38.323 | F18: =$U$19+($U$20*B18)+($U$21*C18) -> 42.888641 | G18: =E18/C18 -> 0.53183547 | H18: ='DRE - Ajustado 3º TRI 2025'!I31/'DRE - Ajustado 3º TRI 2025'!I30 -> 0.088876467 | I18: =E18*(1-H18) -> 34.916987 | U18: Coeficientes | V18: Erro padrão | W18: Stat t | X18: valor-P | Y18: 95% inferiores | Z18: 95% superiores | AA18: Inferior 99,0% | AB18: Superior 99,0%
B19: 2023 | C19: 67.307 | D19: 34.989 | E19: 30.123 | F19: =$U$19+($U$20*B19)+($U$21*C19) -> 33.550643 | G19: =E19/C19 -> 0.44754632 | H19: ='DRE - Ajustado 3º TRI 2025'!J31/'DRE - Ajustado 3º TRI 2025'!J30 -> 0.098042911 | I19: =E19*(1-H19) -> 27.169653 | T19: Interseção | U19: 8613.2945 | V19: 1860.7223 | W19: 4.6290059 | X19: 0.002400499 | Y19: 4213.3854 | Z19: 13013.204 | AA19: 2101.7279 | AB19: 15124.861
B20: 2024 | C20: 85.999 | D20: 47.908 | E20: 43.628 | F20: =$U$19+($U$20*B20)+($U$21*C20) -> 49.187526 | G20: =E20/C20 -> 0.50730822 | H20: ='DRE - Ajustado 3º TRI 2025'!K31/'DRE - Ajustado 3º TRI 2025'!K30 -> 0.23857152 | I20: =E20*(1-H20) -> 33.219602 | T20: ANO | U20: -4.2765443 | V20: 0.92276318 | W20: -4.6344982 | X20: 0.0023850071 | Y20: -6.4585325 | Z20: -2.0945561 | AA20: -7.5057386 | AB20: -1.0473499
B21: 2025 | C21: 75.76 | D21: 41.201 | E21: 36.847 | F21: =$U$19+($U$20*B21)+($U$21*C21) -> 34.002915 | G21: =E21/C21 -> 0.48636484 | H21: ='DRE - Ajustado 3º TRI 2025'!L31/'DRE - Ajustado 3º TRI 2025'!L30 -> 0.29344521 | I21: =E21*(1-H21) -> 26.034424 | T21: Receita | U21: 1.0653449 | V21: 0.090330597 | W21: 11.793844 | X21: 7.1418976e-06 | Y21: 0.85174702 | Z21: 1.2789429 | AA21: 0.74923453 | AB21: 1.3814554
A24: Crescimento da receita nos últimos 6 anos
A25: Anos | D25: 2018 | E25: 2019 | F25: 2020 | G25: 2021 | H25: 2022 | I25: 2023 | J25: 2024 | K25: 2025
A26: Receita | D26: 33.684 | E26: 38.621 | F26: 35.93 | G26: 120.319 | H26: 72.058 | I26: 67.307 | J26: 85.999 | K26: 81.447
A27: g(Receita) | D27: 0 | E27: =E26/D26-1 -> 0.1465681 | F27: =F26/E26-1 -> -0.069677119 | G27: =G26/F26-1 -> 2.3487058 | H27: =H26/G26-1 -> -0.40110872 | I27: =I26/H26-1 -> -0.065932998 | J27: =J26/I26-1 -> 0.27771257 | K27: =K26/J26-1 -> -0.052930848
A30: MÉDIA GEOMÉTRICA DE CRESCIMENTO DA RECEITA DOS ANOS MAIS ESTÁVEIS
A31: g(Receita) | C31: =EXP(C32)-1 -> 0.065889304
A32: ln[1+g(Rec)] | C32: =AVERAGE(E32:K32) -> 0.063809478 | E32: =LN(E27+1) -> 0.13677322 | F32: =LN(F27+1) -> -0.072223569 | J32: =LN(J27+1) -> 0.24507143 | K32: =LN(K27+1) -> -0.054383166
A33: Desvio-padrão (σ) | C33: =_xlfn.STDEV.S(E32:F32,J32:K32) -> 0.15346454
A34: Z score (modelo) | C34: =(C40-C32)/C33 -> -0.089984816
A40: g(Receita) - Cenário | C40: 0.05
A42: Otimista | C42: =EXP(C32+C34*C33)-1 -> 0.051271096
A43: Base | C43: =EXP(C32+0*C33)-1 -> 0.065889304
A44: Pessimista | C44: =EXP(C32-C34*C33)-1 -> 0.080710782
A45: E(g)=m+Zs
A47: Crescimento por Fadeout
A48: taxa inicial | B48: =C31 -> 0.065889304
A49: taxa final | B49: 0.02
A50: n períodos | B50: 8
A51: δ decresc. | B51: =(B48-B49)/B50 -> 0.005736163 | C51: ao ano
...

Sheet Proj. Custos da receita
A1: Ano | B1: 2016 | C1: 2017 | D1: 2018 | E1: 2019 | F1: 2020 | G1: 2021 | H1: 2022 | I1: 2023 | J1: 2024 | P1: CUSTO DE BENS E SERVIÇOS | AM1: DEPRECIAÇÃO E AMORTIZAÇÃO
A2: Receita | B2: 31.353 | C2: 23.646 | D2: 33.684 | E2: 38.621 | F2: 35.93 | G2: 120.319 | H2: 72.058 | I2: 67.307 | J2: 85.999 | P2: "Causas X": RECEITA E ANO | Z2: "Causas X": ANO | AM2: "Causas X": RECEITA, ANO E CUSTO | AW2: "Causas X": Custo de bens e serviços
A3: Custo de bens e serviços | B3: 0 | C3: 10.425 | D3: 10.028 | E3: 13.006 | F3: 12.631 | G3: 13.665 | H3: 27.45 | I3: 32.273 | J3: 38.034 | P3: RESUMO DOS RESULTADOS | Z3: RESUMO DOS RESULTADOS | AC3: MODELO A SER UTILIZADO PARA A PROJEÇÃO | AM3: RESUMO DOS RESULTADOS | AW3: RESUMO DOS RESULTADOS
A4: Depreciação e amortização | B4: 0 | C4: 0 | D4: 0 | E4: 0 | F4: 0 | G4: 0 | H4: 0.06 | I4: 0.045 | J4: 0.057 | AZ4: MODELO A SER UTILIZADO PARA A PROJEÇÃO
A5: Lucro bruto | B5: 17.178 | C5: 13.221 | D5: 23.656 | E5: 25.615 | F5: 23.299 | G5: 106.654 | H5: 44.548 | I5: 34.989 | J5: 47.908 | P5: Estatística de regressão | Z5: Estatística de regressão | AM5: Estatística de regressão | AW5: Estatística de regressão
P6: R múltiplo | Q6: 0.86629102 | Z6: R múltiplo | AA6: 0.84927412 | AM6: R múltiplo | AN6: 0.94556716 | AW6: R múltiplo | AX6: 0.94423086
A7: Ano | B7: Receita | C7: Custo de bens e serviços | D7: Depreciação e amortização | E7: Lucro bruto | P7: R-Quadrado | Q7: 0.75046013 | Z7: R-Quadrado | AA7: 0.72126654 | AM7: R-Quadrado | AN7: 0.89409725 | AW7: R-Quadrado | AX7: 0.89157191
A8: 2016 | B8: 31.353 | C8: 14.175 | D8: 0 | E8: 17.178 | P8: R-quadrado ajustado | Q8: 0.66728018 | Z8: R-quadrado ajustado | AA8: 0.68144747 | AM8: R-quadrado ajustado | AN8: 0.83055561 | AW8: R-quadrado ajustado | AX8: 0.87608218
A9: 2017 | B9: 23.646 | C9: 10.425 | D9: 0 | E9: 13.221 | P9: Erro padrão | Q9: 6.0911011 | Z9: Erro padrão | AA9: 5.9600101 | AM9: Erro padrão | AN9: 0.011233597 | AW9: Erro padrão | AX9: 0.0096066537
A10: 2018 | B10: 33.684 | C10: 10.028 | D10: 0 | E10: 23.656 | P10: Observações | Q10: 9 | Z10: Observações | AA10: 9 | AM10: Observações | AN10: 9 | AW10: Observações | AX10: 9
A11: 2019 | B11: 38.621 | C11: 13.006 | D11: 0 | E11: 25.615
A12: 2020 | B12: 35.93 | C12: 12.631 | D12: 0 | E12: 23.299 | P12: ANOVA | Z12: ANOVA | AM12: ANOVA | AW12: ANOVA
A13: 2021 | B13: 120.319 | C13: 13.665 | D13: 0 | E13: 106.654 | Q13: gl | R13: SQ | S13: MQ | T13: F | U13: F de significação | AA13: gl | AB13: SQ | AC13: MQ | AD13: F | AE13: F de significação | AN13: gl | AO13: SQ | AP13: MQ | AQ13: F | AR13: F de significação | AX13: gl | AY13: SQ | AZ13: MQ | BA13: F | BB13: F de significação
A14: 2022 | B14: 72.058 | C14: 27.45 | D14: 0.06 | E14: 44.548 | P14: Regressão | Q14: 2 | R14: 669.46912 | S14: 334.73456 | T14: 9.0221271 | U14: 0.015538884 | Z14: Regressão | AA14: 1 | AB14: 643.42615 | AC14: 643.42615 | AD14: 18.113598 | AE14: 0.0037650974 | AM14: Regressão | AN14: 3 | AO14: 0.0053270314 | AP14: 0.0017756771 | AQ14: 14.071043 | AR14: 0.0071480164 | AW14: Regressão | AX14: 1 | AY14: 0.0053119854 | AZ14: 0.0053119854 | BA14: 57.558915 | BB14: 0.00012768217
A15: 2023 | B15: 67.307 | C15: 32.273 | D15: 0.045 | E15: 34.989 | P15: Resíduo | Q15: 6 | R15: 222.60908 | S15: 37.101513 | Z15: Resíduo | AA15: 7 | AB15: 248.65205 | AC15: 35.521721 | AM15: Resíduo | AN15: 5 | AO15: 0.00063096855 | AP15: 0.00012619371 | AW15: Resíduo | AX15: 7 | AY15: 0.00064601457 | AZ15: 9.2287796e-05
A16: 2024 | B16: 85.999 | C16: 38.034 | D16: 0.057 | E16: 47.908 | P16: Total | Q16: 8 | R16: 892.0782 | Z16: Total | AA16: 8 | AB16: 892.0782 | AM16: Total | AN16: 8 | AO16: 0.005958 | AW16: Total | AX16: 8 | AY16: 0.005958
Q18: Coeficientes | R18: Erro padrão | S18: Stat t | T18: valor-P | U18: 95% inferiores | V18: 95% superiores | W18: Inferior 99,0% | X18: Superior 99,0% | AA18: Coeficientes | AB18: Erro padrão | AC18: Stat t | AD18: valor-P | AE18: 95% inferiores | AF18: 95% superiores | AG18: Inferior 99,0% | AH18: Superior 99,0% | AN18: Coeficientes | AO18: Erro padrão | AP18: Stat t | AQ18: valor-P | AR18: 95% inferiores | AS18: 95% superiores | AT18: Inferior 99,0% | AU18: Superior 99,0% | AX18: Coeficientes | AY18: Erro padrão | AZ18: Stat t | BA18: valor-P | BB18: 95% inferiores | BC18: 95% superiores | BD18: Inferior 99,0% | BE18: Superior 99,0%
P19: Interseção | Q19: -7975.5207 | R19: 2287.9933 | S19: -3.4858146 | T19: 0.013049706 | U19: -13574.039 | V19: -2377.0026 | W19: -16458.091 | X19: 507.04999 | Z19: Interseção | AA19: -6595.8513 | AB19: 1554.2579 | AC19: -4.2437302 | AD19: 0.0038226352 | AE19: -10271.087 | AF19: -2920.6153 | AG19: -12034.951 | AH19: -1156.7516 | AM19: Interseção | AN19: -2.0766143 | AO19: 7.3392436 | AP19: -0.28294664 | AQ19: 0.78855787 | AR19: -20.942741 | AS19: 16.789512 | AT19: -31.669494 | AU19: 27.516265 | AW19: Interseção | AX19: -0.028550235 | AY19: 0.0069210741 | AZ19: -4.1251162 | BA19: 0.004431035 | BB19: -0.044915975 | BC19: -0.012184495 | BD19: -0.052770418 | BE19: -0.0043300516
P20: Ano | Q20: 3.9599869 | R20: 1.1346174 | S20: 3.4901518 | T20: 0.012980959 | U20: 1.1836782 | V20: 6.7362957 | W20: -0.2465254 | X20: 8.1664993 | Z20: Ano | AA20: 3.2747167 | AB20: 0.769434 | AC20: 4.2560072 | AD20: 0.0037650974 | AE20: 1.4552944 | AF20: 5.094139 | AG20: 0.58209524 | AH20: 5.9673381 | AM20: Ano | AN20: 0.0010168821 | AO20: 0.0036425678 | AP20: 0.27916628 | AQ20: 0.79129613 | AR20: -0.0083466366 | AS20: 0.010380401 | AT20: -0.013670472 | AU20: 0.015704236 | AW20: Custo de bens e serviços | AX20: 0.0024402087 | AY20: 0.00032164046 | AZ20: 7.5867592 | BA20: 0.00012768217 | BB20: 0.0016796499 | BC20: 0.0032007675 | BD20: 0.0013146333 | BE20: 0.0035657841
P21: Receita | Q21: -0.080935361 | R21: 0.096602611 | S21: -0.83781753 | T21: 0.43423173 | U21: -0.31731343 | V21: 0.15544271 | W21: -0.43908259 | X21: 0.27721187 | AM21: Receita | AN21: -6.3377122e-05 | AO21: 0.00018829401 | AP21: -0.33658598 | AQ21: 0.75009618 | AR21: -0.00054740228 | AS21: 0.00042064803 | AT21: -0.00082260548 | AU21: 0.00069585124
AM22: Custo de bens e serviços | AN22: 0.0023115663 | AO22: 0.00075291755 | AP22: 3.0701453 | AQ22: 0.027779212 | AR22: 0.00037613008 | AS22: 0.0042470025 | AT22: -0.00072430496 | AU22: 0.0053474375
A23: PROJEÇÃO (ESPERADO)
A24: Ano | B24: 2025 | C24: 2026 | D24: 2027 | E24: 2028 | F24: 2029 | G24: 2030 | H24: 2031 | I24: 2032 | J24: 2033 | K24: 2034 | AM24: "Causas X": RECEITA E CUSTO
A25: Custo de bens e serviços | B25: =$AA$19+($AA$20*B24) -> 35.449917 | C25: =$AA$19+($AA$20*C24) -> 38.724633 | D25: =$AA$19+($AA$20*D24) -> 41.99935 | E25: =$AA$19+($AA$20*E24) -> 45.274067 | F25: =$AA$19+($AA$20*F24) -> 48.548783 | G25: =$AA$19+($AA$20*G24) -> 51.8235 | H25: =$AA$19+($AA$20*H24) -> 55.098217 | I25: =$AA$19+($AA$20*I24) -> 58.372933 | ... K25: =$AA$19+($AA$20*K24) -> 64.922367 | AM25: RESUMO DOS RESULTADOS
A26: Depreciação e amortização | B26: =$AX$19+($AX$20*B25) -> 0.057954961 | C26: =$AX$19+($AX$20*C25) -> 0.065945953 | D26: =$AX$19+($AX$20*D25) -> 0.073936945 | E26: =$AX$19+($AX$20*E25) -> 0.081927937 | F26: =$AX$19+($AX$20*F25) -> 0.089918929 | G26: =$AX$19+($AX$20*G25) -> 0.097909922 | H26: =$AX$19+($AX$20*H25) -> 0.10590091 | I26: =$AX$19+($AX$20*I25) -> 0.11389191 | ... K26: =$AX$19+($AX$20*K25) -> 0.12987389
AM27: Estatística de regressão
AM28: R múltiplo | AN28: 0.9446939
AM29: R-Quadrado | AN29: 0.89244657
AM30: R-quadrado ajustado | AN30: 0.85659543
AM31: Erro padrão | AN31: 0.010334435
AM32: Observações | AN32: 9
AM34: ANOVA
AN35: gl | AO35: SQ | AP35: MQ | AQ35: F | AR35: F de significação
AM36: Regressão | AN36: 2 | AO36: 0.0053171967 | AP36: 0.0026585983 | AQ36: 24.893114 | AR36: 0.00124415
AM37: Resíduo | AN37: 6 | AO37: 0.00064080331 | AP37: 0.00010680055
AM38: Total | AN38: 8 | AO38: 0.005958
AN40: Coeficientes | AO40: Erro padrão | AP40: Stat t | AQ40: valor-P | AR40: 95% inferiores | AS40: 95% superiores | AT40: Inferior 99,0% | AU40: Superior 99,0%
AM41: Interseção | AN41: -0.027746532 | AO41: 0.0082868556 | AP41: -3.3482582 | AQ41: 0.015452687 | AR41: -0.048023737 | AS41: -0.0074693271 | AT41: -0.058469453 | AU41: 0.0029763884
AM42: Receita | AN42: -2.8855599e-05 | AO42: 0.00013063075 | AP42: -0.22089438 | AQ42: 0.8324998 | AR42: -0.00034849753 | AS42: 0.00029078633 | AT42: -0.0005131597 | AU42: 0.0004554485
AM43: Custo de bens e serviços | AN43: 0.002483612 | AO43: 0.00039790569 | AP43: 6.2417102 | AQ43: 0.00078322756 | AR43: 0.0015099718 | AS43: 0.0034572522 | AT43: 0.0010084053 | AU43: 0.0039588187

Sheet Proj. Despesas Operacionais
A1: Ano | B1: 2016 | C1: 2017 | D1: 2018 | E1: 2019 | F1: 2020 | G1: 2021 | H1: 2022 | I1: 2023 | J1: 2024 | P1: Venda e marketing | AN1: Geral e administrativas | BJ1: Pesquisa e desenvolvimento | CG1: Depreciação e amortização:
A2: Receita | B2: 31.353 | C2: 23.646 | D2: 33.684 | E2: 38.621 | F2: 35.93 | G2: 120.319 | H2: 72.058 | I2: 67.307 | J2: 85.999 | P2: "Causas X": RECEITA E ANO | Z2: "Causas X": RECEITA E CUSTO DE VENDA | AN2: "Causas X": RECEITA E ANO | AX2: "Causas X": RECEITA(t-1) E ANO | BJ2: "Causas X": RECEITA(t-1) | BS2: "Causas X": RECEITA(t-1) e ANO | CG2: "Causas X": RECEITA, CUSTO DE BENS E ANO | CP2: "Causas X": CUSTO DE BENS E SERVIÇOS
